Workbook

Sheet 📊 SYNTHESE
A1: BUDGET MASTER GÉNIE 2026 — SYNTHÈSE DE DIRECTION
A2: Tiers-Lieu Génie · 12 rue du Génie 82000 Montauban · Dernière mise à jour : 17/04/2026
A4: 1 · INDICATEURS CLÉS — ANNÉE 2026 (scénario médian)
A5: Chiffre d'affaires prévisionnel HT | E5: ='📈 Compte de résultat'!N19 -> 26204.72
A6: Total charges d'exploitation | E6: ='📈 Compte de résultat'!N33 -> 24254.84
A7: Résultat net 2026 | E7: ='📈 Compte de résultat'!N35 -> 1949.88
A8: Trésorerie en fin d'année (solde cumulé) | E8: ='💧 Trésorerie'!N13 -> -4954.84
A9: Seuil de rentabilité mensuel (point mort) | E9: ='📈 Compte de résultat'!B37 -> 2883.1933
A10: Taux d'occupation moyen des bureaux privatifs | E10: ='💰 Revenus'!N11 -> 0.35416667
A11: Nombre de bureaux privatifs loués (moyenne 2026) | E11: ='💰 Revenus'!N12 -> 2.8333333
A13: 2 · LOCATAIRES SIGNÉS (source : dossiers Contrats clients en cours)
A14: Locataire | B14: Statut | C14: Espace | D14: Surface | E14: Formule | F14: Loyer HC/mois | G14: Charges/mois | H14: Total TCC/mois
A15: OVNI-Graphics | B15: Signé 18/03/2026 | C15: Bureau 1-09 Baden POWELL | D15: 16 m² | E15: Bail 1 an + badge + cave | F15: 208 | G15: 47.84 | H15: =F15+G15+35 -> 290.84
A16: Antre-Connaissance | B16: Convention signée | C16: Salle de réunion (1h/sem) | D16: - | E16: Convention usage salle — 1h/semaine | F16: 80 | G16: 0 | H16: =F16+G16+35 -> 115
A17: FNE | B17: Convention signée | C17: Accès conventionné | D17: - | E17: Partenariat | F17: 300 | G17: 46 | H17: =F17+G17+35 -> 381
A18: MOBICOOP | B18: Convention Juillet | C18: 1-07 Aimée CÉSAIRE + 1-08 CONDORCET | D18: 34 m² | E18: Bail 3/6/9 (15€/m²) — dès 01/07/2026 | F18: 510 | G18: 117.3 | H18: =F18+G18+10 -> 637.3
A19: ↳ MOBICOOP : recettes effectives juillet–décembre 2026 uniquement (6 × 637,30 € = 3 823,80 €/an)
A20: Nadine DAUGE
A21: TOTAL mensuel (signés + conventions — hors MOBICOOP S1) | F21: =SUM(F15:F20) -> 1098 | G21: =SUM(G15:G20) -> 211.14 | H21: =SUM(H15:H20) -> 1424.14
A22: 3 · SCÉNARIOS DE REMPLISSAGE — RÉSULTAT 2026
A23: Scénario | B23: Taux occ. bureaux | C23: Cowork abo. | D23: Salles/mois | E23: CA 2026 | F23: Charges 2026 | G23: Résultat | H23: Commentaire
A24: 🔴 BAS (prudent) | B24: 0.25 | C24: 2 | D24: 3 | E24: ='🎯 Scenarios'!B27 -> 0 | F24: ='🎯 Scenarios'!B28 -> 0 | G24: ='🎯 Scenarios'!B29 -> 0 | H24: Ne couvre pas les charges, perte > 8 k€
A25: 🟡 MÉDIAN (cible) | B25: 0.4 | C25: 5 | D25: 6 | E25: ='🎯 Scenarios'!D27 -> 0 | F25: ='🎯 Scenarios'!D28 -> 0 | G25: ='🎯 Scenarios'!D29 -> 0 | H25: Équilibre atteint en fin d'année
A26: 🟢 HAUT (optimiste) | B26: 0.6 | C26: 10 | D26: 10 | E26: ='🎯 Scenarios'!F27 -> 0 | F26: ='🎯 Scenarios'!F28 -> 0 | G26: ='🎯 Scenarios'!F29 -> 0 | H26: Excédent à réinvestir
A29: 4 · ALERTES & RECOMMANDATIONS
A30: ⚠️ Trésorerie | B30: Mois le plus bas en 2026 : | E30: ='💧 Trésorerie'!C16 -> -4954.84 | F30: Besoin de fonds de roulement à sécuriser via avance CCFA (8 000 €)
A31: ⚠️ Taxe foncière | B31: Décaissement en octobre 2026 : | E31: 4200 | F31: Provisionner 350 €/mois dès janvier pour éviter un trou de trésorerie
A32: 📌 Loyer | B32: Palier passage loyer plein dès juillet 2026 : | E32: 1950 | F32: Préparer le CA à supporter ce palier (janv-juin = 250 €, juil-déc = 1 950 €)
A33: ✅ Priorité | B33: CA minimum mensuel à sécuriser dès Juillet 2026 : | E33: ='📈 Compte de résultat'!B37 -> 2883.1933 | F33: Couvrir loyer + charges fixes pour passer le cap de juillet

Sheet ⚙️ Hypothèses
A1: HYPOTHÈSES & GRILLE TARIFAIRE OFFICIELLE 2026
A2: Source : Grille tarifaire Génie-Bon-définitif.pdf (avril 2026) — tarifs applicables à tous les NOUVEAUX contrats
A4: 🏢 BUREAUX PRIVATIFS (source grille officielle — tarifs HC €/m²/mois)
A5: Bureau | B5: Nom | C5: Étage | D5: Surface m² | E5: €/m² Mensuel | F5: €/m² Bail 1 an | G5: €/m² Bail 3/6/9 | H5: Loyer Mensuel | I5: Loyer 1 an | J5: Loyer 3/6/9
A6: 0-01 | B6: Louise MICHEL | C6: RDC | D6: 15 | E6: 18 | F6: 17 | G6: 15 | H6: =D6*E6 -> 270 | I6: =D6*F6 -> 255 | J6: =D6*G6 -> 225
A7: 0-03 | B7: Philippe MEIRIEU | C7: RDC | D7: 24 | E7: 18 | F7: 17 | G7: 15 | H7: =D7*E7 -> 432 | I7: =D7*F7 -> 408 | J7: =D7*G7 -> 360
A8: 0-04 | B8: Antoine LAVOISIER | C8: RDC | D8: 19 | E8: 18 | F8: 17 | G8: 15 | H8: =D8*E8 -> 342 | I8: =D8*F8 -> 323 | J8: =D8*G8 -> 285
A9: 1-07 | B9: Aimée CÉSAIRE | C9: 1er | D9: 17 | E9: 18 | F9: 17 | G9: 15 | H9: =D9*E9 -> 306 | I9: =D9*F9 -> 289 | J9: =D9*G9 -> 255
A10: 1-08 | B10: CONDORCET | C10: 1er | D10: 17 | E10: 18 | F10: 17 | G10: 15 | H10: =D10*E10 -> 306 | I10: =D10*F10 -> 289 | J10: =D10*G10 -> 255
A11: 1-09 | B11: Baden POWELL | C11: 1er | D11: 16 | E11: 18 | F11: 17 | G11: 15 | H11: =D11*E11 -> 288 | I11: =D11*F11 -> 272 | J11: =D11*G11 -> 240
A12: 1-11 | B12: Célestin FREINET | C12: 1er | D12: 24 | E12: 18 | F12: 17 | G12: 15 | H12: =D12*E12 -> 432 | I12: =D12*F12 -> 408 | J12: =D12*G12 -> 360
A13: -1-14 | B13: Maria MONTESSORI | C13: Rez-jardin | D13: 12 | E13: 18 | F13: 17 | G13: 15 | H13: =D13*E13 -> 216 | I13: =D13*F13 -> 204 | J13: =D13*G13 -> 180
A14: TOTAL 100% occ. | D14: =SUM(D6:D13) -> 144 | H14: =SUM(H6:H13) -> 2592 | I14: =SUM(I6:I13) -> 2448 | J14: =SUM(J6:J13) -> 2160
A16: 💼 COWORKING / BUREAUX NOMADES (source grille officielle)
A17: Bureau | B17: Nom | C17: Type | D17: Surface | E17: ½ Journée | F17: Journée | G17: Semaine | H17: Mois
A18: 1-13 | B18: ARISTOTE | C18: Privé | D18: 7 m² | E18: 12 | F18: 22 | G18: 90 | H18: 200
A19: 1-10 | B19: Jean-Jacques ROUSSEAU | C19: Coworking | D19: 28 m² | E19: 10 | F19: 17 | G19: 60 | H19: 180
A20: -1-14 | B20: Maria MONTESSORI (PMR) | C20: Privé | D20: 12 m² | E20: 15 | F20: 27 | G20: 100 | H20: 216
A23: 🪑 SALLES DE RÉUNION (source grille officielle)
A24: Salle | B24: Capacité | C24: Unité | D24: Tarif CCFA | E24: Adhérent Génie | F24: Locataire | G24: Asso locale
A25: Antoine BOURDELLE (0-02) | B25: 40 p | C25: Heure | D25: 40 | E25: 30 | F25: 20 | G25: GRATUIT
A26: Antoine BOURDELLE (0-02) | B26: 40 p | C26: ½ journée (4h) | D26: 110 | E26: 90 | F26: 70 | G26: GRATUIT
A27: Antoine BOURDELLE (0-02) | B27: 40 p | C27: Journée (8h) | D27: 180 | E27: 150 | F27: 120 | G27: GRATUIT
A28: Célestin FREINET (1-11) | B28: 20 p | C28: Heure | D28: 30 | E28: 20 | F28: 15 | G28: GRATUIT
A29: Célestin FREINET (1-11) | B29: 20 p | C29: ½ journée (4h) | D29: 90 | E29: 60 | F29: 45 | G29: GRATUIT
A30: Célestin FREINET (1-11) | B30: 20 p | C30: Journée (8h) | D30: 150 | E30: 100 | F30: 80 | G30: GRATUIT
A31: Olympe DE GOUGES (1-12) | B31: 20 p | C31: Heure | D31: 30 | E31: 20 | F31: 15 | G31: GRATUIT
A32: Olympe DE GOUGES (1-12) | B32: 20 p | C32: ½ journée (4h) | D32: 90 | E32: 60 | F32: 45 | G32: GRATUIT
A33: Olympe DE GOUGES (1-12) | B33: 20 p | C33: Journée (8h) | D33: 150 | E33: 100 | F33: 80 | G33: GRATUIT
A34: Maria MONTESSORI (PMR, -1-14) | B34: 4 p | C34: Heure | D34: 20 | E34: 15 | F34: 10 | G34: GRATUIT
A35: Maria MONTESSORI (PMR, -1-14) | B35: 4 p | C35: ½ journée (4h) | D35: 60 | E35: 45 | F35: 30 | G35: GRATUIT
A36: Maria MONTESSORI (PMR, -1-14) | B36: 4 p | C36: Journée (8h) | D36: 100 | E36: 80 | F36: 70 | G36: GRATUIT
A39: ➕ SERVICES COMPLÉMENTAIRES & ADHÉSIONS
A40: Service | B40: Tarif | C40: Base | D40: Commentaire
A41: Accès 24h/7j (badge) | B41: 5 | C41: / mois | D41: Supplément hors horaires et jours d'ouverture
A42: Domiciliation entreprise | B42: 45 | C42: / mois | D42: Tarif révisé prévisionnel 30/03/2026
A43: Location cave | B43: 30 | C43: / mois | D43: Option applicable selon disponibilité (ex : OVNI)
A44: Adhésion particulier modeste | B44: 30 | C44: / an | D44: Barème progressif 30 / 45 / 60 / 80 €
A45: Adhésion particulier standard | B45: 45 | C45: / an | D45: Tarif médian
A46: Adhésion particulier soutien | B46: 80 | C46: / an | D46: Tarif soutien (soutien à l'association)
...

Sheet 👥 Locataires
A1: LOCATAIRES & CONTRATS 2026
A2: Sources : dossiers "02 - Commercial/Contrats clients en cours" + grille tarifaire officielle
A4: ✅ LOCATAIRES AVEC CONTRAT SIGNÉ
A5: Locataire | B5: Type structure | C5: Bureau | D5: Surface | E5: Formule | F5: Date effet | G5: Loyer HC €/mois | H5: Charges €/mois | I5: Options €/mois | J5: Total TCC €/mois
A6: OVNI-Graphics (Loic Langloys) | B6: EURL | C6: 1-09 Baden POWELL | D6: 16 | E6: Bail 1 an (tarif révisé 13€/m²) | F6: 01/04/2026 | G6: 208 | H6: 47.84 | I6: 35 | J6: =G6+H6+I6 -> 290.84
A7: Nadine DAUGE | B7: Particulier / indép. | C7: -1-14 Maria MONTESSORI | D7: 12 | E7: Bail 1 an — 1j/semaine | F7: 01/04/2026 | G7: 93 | H7: 20.24 | I7: 35 | J7: =G7+H7+I7 -> 148.24
A8: MOBICOOP (Montauban) | G8: 510 | H8: 117.3 | I8: 10 | J8: =G8+H8+I8 -> 637.3
A9: ↳ MOBICOOP : recettes effectives à partir de juillet 2026 uniquement (6 mois × 637,30 € = 3 823,80 €/an)
A11: TOTAL RECETTES CONTRATS SIGNÉS | G11: =SUM(G6:G9) -> 811 | H11: =SUM(H6:H9) -> 185.38 | I11: =SUM(I6:I9) -> 80 | J11: =SUM(J6:J9) -> 1076.38
A13: 🔄 LOCATAIRES EN COURS / PARTENARIATS
A14: Locataire | B14: Type structure | C14: Bureau | D14: Surface | E14: Formule | F14: Date effet | G14: Loyer HC €/mois | H14: Charges €/mois | I14: Options €/mois | J14: Total TCC €/mois
A15: Antre-Connaissance (Eddy Cherif) | B15: Association | C15: Salle de réunion (1h/semaine) | D15: 0 | E15: Convention usage salle — 1h/semaine | F15: 2026 | G15: 80 | H15: 0 | I15: 35 | J15: =G15+H15+I15 -> 115
A16: FNE — Formation Continue (Fédération)
A17: TOTAL RECETTES CONVENTIONS (hors MOBICOOP S1) | G17: =SUM(G15:G16) -> 80 | H17: =SUM(H15:H16) -> 0 | I17: =SUM(I15:I16) -> 35 | J17: =SUM(J15:J16) -> 115
A18: ★ TOTAL CA LOCATAIRES & CONVENTIONS (annualisé) | G18: =G11 + G17 + (510*6) -> 3951 | H18: =H11 + H17 + (117.3*6) -> 889.18 | I18: =I11 + I17 + (10*6) -> 175 | J18: =J11 + J17 + (637.3*6) -> 5015.18
A19: ⚠ MOBICOOP comptabilisé sur 6 mois (juillet–décembre 2026) : 510 HC + 117,30 charges + 10 badges = 637,30 €/mois × 6 = 3 823,80 €
A20: Bureau | B20: Nom | C20: Surface | D20: Mensuel (18€/m²) | E20: 1 an (17€/m²) | F20: 3/6/9 (15€/m²) | G20: Commentaire
A21: 0-01 | B21: Louise MICHEL | C21: 15 | D21: 270 | E21: 255 | F21: 225 | G21: Priorité n°1 (RDC accessible)
A22: 0-04 | B22: Antoine LAVOISIER | C22: 19 | D22: 342 | E22: 323 | F22: 285 | G22: RDC
A23: 1-08 | C23: 17 | D23: 306 | E23: 289 | F23: 255 | G23: 1er étage
A24: 1-11 | B24: Célestin FREINET | C24: 24 | D24: 432 | E24: 408 | F24: 360 | G24: Grand bureau 1er
A25: POTENTIEL MAX (100%) | C25: =SUM(C21:C24) -> 75 | D25: =SUM(D21:D24) -> 1350 | E25: =SUM(E21:E24) -> 1275 | F25: =SUM(F21:F24) -> 1125 | G25: CA mensuel HC bureaux si 100% occupés

Sheet 💰 Revenus
A1: REVENUS MENSUELS PRÉVISIONNELS 2026
A2: Scénario médian · taux occ. bureaux croissant · appui sur contrat OVNI signé + hypothèses révisées 30/03/2026
A4: 🏢 BUREAUX PRIVATIFS (base 8 bureaux × tarif moy. pondéré)
A5: Ligne | B5: Jan | C5: Fév | D5: Mar | E5: Avr | F5: Mai | G5: Juin | H5: Juil | I5: Août | J5: Sep | K5: Oct | L5: Nov | M5: Déc | N5: TOTAL
A6: Taux d'occupation | B6: 0.125 | C6: 0.125 | D6: 0.25 | E6: 0.25 | F6: 0.25 | G6: 0.25 | H6: 0.375 | I6: 0.375 | J6: 0.5 | K6: 0.5 | L6: 0.625 | M6: 0.625 | N6: =AVERAGE(B6:M6) -> 0.35416667
A7: CA potentiel bureaux 100% (€/mois) | B7: ='⚙️ Hypothèses'!$I$14 -> 2448 | C7: ='⚙️ Hypothèses'!$I$14 -> 2448 | D7: ='⚙️ Hypothèses'!$I$14 -> 2448 | E7: ='⚙️ Hypothèses'!$I$14 -> 2448 | F7: ='⚙️ Hypothèses'!$I$14 -> 2448 | G7: ='⚙️ Hypothèses'!$I$14 -> 2448 | H7: ='⚙️ Hypothèses'!$I$14 -> 2448 | I7: ='⚙️ Hypothèses'!$I$14 -> 2448 | ... M7: ='⚙️ Hypothèses'!$I$14 -> 2448 | N7: =B7 -> 2448
A8: ▶ CA bureaux privatifs (€) | B8: =B6*B7 -> 306 | C8: =C6*C7 -> 306 | D8: =D6*D7 -> 612 | E8: =E6*E7 -> 612 | F8: =F6*F7 -> 612 | G8: =G6*G7 -> 612 | H8: =H6*H7 -> 918 | I8: =I6*I7 -> 918 | ... M8: =M6*M7 -> 1530 | N8: =SUM(B8:M8) -> 10404
A9: + Charges refacturées (23% loyer) | B9: =B8*0.23 -> 70.38 | C9: =C8*0.23 -> 70.38 | D9: =D8*0.23 -> 140.76 | E9: =E8*0.23 -> 140.76 | F9: =F8*0.23 -> 140.76 | G9: =G8*0.23 -> 140.76 | H9: =H8*0.23 -> 211.14 | I9: =I8*0.23 -> 211.14 | ... M9: =M8*0.23 -> 351.9 | N9: =SUM(B9:M9) -> 2392.92
A11: KPI · Taux d'occupation moyen | B11: =B6 -> 0.125 | C11: =C6 -> 0.125 | D11: =D6 -> 0.25 | E11: =E6 -> 0.25 | F11: =F6 -> 0.25 | G11: =G6 -> 0.25 | H11: =H6 -> 0.375 | I11: =I6 -> 0.375 | ... M11: =M6 -> 0.625 | N11: =AVERAGE(B11:M11) -> 0.35416667
A12: KPI · Nb bureaux occupés (sur 8) | B12: =B6*8 -> 1 | C12: =C6*8 -> 1 | D12: =D6*8 -> 2 | E12: =E6*8 -> 2 | F12: =F6*8 -> 2 | G12: =G6*8 -> 2 | H12: =H6*8 -> 3 | I12: =I6*8 -> 3 | ... M12: =M6*8 -> 5 | N12: =AVERAGE(B12:M12) -> 2.8333333
A13: 📋 RECETTES LOCATAIRES SIGNÉS & CONVENTIONS (TCC — recettes certaines)
A14: OVNI-Graphics (Baden Powell — bail 1 an, dès avr. 2026)
A15: Nadine DAUGE (Montessori — 1j/sem, bail 1 an) | B15: 148.24 | C15: 148.24 | D15: 148.24 | E15: 148.24 | F15: 148.24 | G15: 148.24 | H15: 148.24 | I15: 148.24 | J15: 148.24 | K15: 148.24 | L15: 148.24 | M15: 148.24 | N15: 1778.88
A16: FNE — Bureau Philippe Meirieu (convention partenariat 2026) | B16: 381 | C16: 381 | D16: 381 | E16: 381 | F16: 381 | G16: 381 | H16: 381 | I16: 381 | J16: 381 | K16: 381 | L16: 381 | M16: 381 | N16: 4572
A17: Antre-Connaissance — convention salle (1h/semaine) | B17: 115 | C17: 115 | D17: 115 | E17: 115 | F17: 115 | G17: 115 | H17: 115 | I17: 115 | J17: 115 | K17: 115 | L17: 115 | M17: 115 | N17: 1380
A18: MOBICOOP — Césaire + Condorcet (bail 3/6/9, 15€/m² — dès 01/07/2026) | B18: 0 | C18: 0 | D18: 0 | E18: 0 | F18: 0 | G18: 0 | H18: 637.3 | I18: 637.3 | J18: 637.3 | K18: 637.3 | L18: 637.3 | M18: 637.3 | N18: 3823.8
A19: ↳ MOBICOOP : 510€ HC + 117,30€ charges + 10€ badges × 6 mois = 3 823,80€/an
A20: 📌 REPÈRE — Total locataires & conventions TCC (à ne pas sommer au CA : déjà intégré via taux occ.) | B20: 644.24 | C20: 644.24 | D20: 644.24 | E20: 935.08 | F20: 935.08 | G20: 935.08 | H20: 1572.38 | I20: 1572.38 | J20: 1572.38 | K20: 1572.38 | L20: 1572.38 | M20: 1572.38 | N20: 14172.24
A21: 💼 COWORKING — POSTES NOMADES & ABONNEMENTS
A22: Ligne | B22: Jan | C22: Fév | D22: Mar | E22: Avr | F22: Mai | G22: Juin | H22: Juil | I22: Août | J22: Sep | K22: Oct | L22: Nov | M22: Déc | N22: TOTAL
A23: Passages journée (nb) | B23: 0 | C23: 0 | D23: 4 | E23: 8 | F23: 10 | G23: 12 | H23: 12 | I23: 8 | J23: 15 | K23: 18 | L23: 20 | M23: 22
A24: Tarif journée coworking (€) | B24: ='⚙️ Hypothèses'!$F$19 -> 17 | C24: ='⚙️ Hypothèses'!$F$19 -> 17 | D24: ='⚙️ Hypothèses'!$F$19 -> 17 | E24: ='⚙️ Hypothèses'!$F$19 -> 17 | F24: ='⚙️ Hypothèses'!$F$19 -> 17 | G24: ='⚙️ Hypothèses'!$F$19 -> 17 | H24: ='⚙️ Hypothèses'!$F$19 -> 17 | I24: ='⚙️ Hypothèses'!$F$19 -> 17 | ... M24: ='⚙️ Hypothèses'!$F$19 -> 17 | N24: =B17 -> 115
A25: ▶ CA coworking journée (€) | B25: =B23*B24 -> 0 | C25: =C23*C24 -> 0 | D25: =D23*D24 -> 68 | E25: =E23*E24 -> 136 | F25: =F23*F24 -> 170 | G25: =G23*G24 -> 204 | H25: =H23*H24 -> 204 | I25: =I23*I24 -> 136 | ... M25: =M23*M24 -> 374 | N25: =SUM(B25:M25) -> 2193
A26: Abonnements mensuels actifs (nb) | B26: 0 | C26: 1 | D26: 2 | E26: 3 | F26: 4 | G26: 5 | H26: 5 | I26: 4 | J26: 6 | K26: 7 | L26: 8 | M26: 9 | N26: =AVERAGE(B26:M26) -> 4.5
A27: Tarif abonnement mensuel (€) | B27: ='⚙️ Hypothèses'!$H$19 -> 180 | C27: ='⚙️ Hypothèses'!$H$19 -> 180 | D27: ='⚙️ Hypothèses'!$H$19 -> 180 | E27: ='⚙️ Hypothèses'!$H$19 -> 180 | F27: ='⚙️ Hypothèses'!$H$19 -> 180 | G27: ='⚙️ Hypothèses'!$H$19 -> 180 | H27: ='⚙️ Hypothèses'!$H$19 -> 180 | I27: ='⚙️ Hypothèses'!$H$19 -> 180 | ... M27: ='⚙️ Hypothèses'!$H$19 -> 180
A28: ▶ CA abonnements coworking (€) | B28: =B26*B27 -> 0 | C28: =C26*C27 -> 180 | D28: =D26*D27 -> 360 | E28: =E26*E27 -> 540 | F28: =F26*F27 -> 720 | G28: =G26*G27 -> 900 | H28: =H26*H27 -> 900 | I28: =I26*I27 -> 720 | ... M28: =M26*M27 -> 1620 | N28: =SUM(B28:M28) -> 9720
A30: 🪑 SALLES DE RÉUNION (tarif moyen pondéré ~ 115€ / réservation)
A31: Ligne | B31: Jan | C31: Fév | D31: Mar | E31: Avr | F31: Mai | G31: Juin | H31: Juil | I31: Août | J31: Sep | K31: Oct | L31: Nov | M31: Déc | N31: TOTAL
A32: Nb réservations / mois | B32: 2 | C32: 3 | D32: 4 | E32: 3 | F32: 5 | G32: 7 | H32: 4 | I32: 3 | J32: 7 | K32: 8 | L32: 9 | M32: 9 | N32: =SUM(B32:M32) -> 64
A33: Tarif moyen / résa (€) | B33: 115 | C33: 115 | D33: 115 | E33: 115 | F33: 115 | G33: 115 | H33: 115 | I33: 115 | J33: 115 | K33: 115 | L33: 115 | M33: 115
A34: ▶ CA salles de réunion (€) | B34: =B32*B33 -> 230 | C34: =C32*C33 -> 345 | D34: =D32*D33 -> 460 | E34: =E32*E33 -> 345 | F34: =F32*F33 -> 575 | G34: =G32*G33 -> 805 | H34: =H32*H33 -> 460 | I34: =I32*I33 -> 345 | ... M34: =M32*M33 -> 1035 | N34: =SUM(B34:M34) -> 7360
A36: ➕ SERVICES COMPLÉMENTAIRES (domiciliation, badges, adhésions)
A37: Ligne
A38: Domiciliations actives (nb) | B38: 0 | C38: 0 | D38: 1 | E38: 1 | F38: 2 | G38: 2 | H38: 2 | I38: 2 | J38: 3 | K38: 4 | L38: 4 | M38: 4 | N38: =AVERAGE(B38:M38) -> 2.0833333
A39: ▶ CA domiciliation (45 €/mois) | B39: =B38*45 -> 0 | C39: =C38*45 -> 0 | D39: =D38*45 -> 45 | E39: =E38*45 -> 45 | F39: =F38*45 -> 90 | G39: =G38*45 -> 90 | H39: =H38*45 -> 90 | I39: =I38*45 -> 90 | ... M39: =M38*45 -> 180 | N39: =SUM(B39:M39) -> 1125
A40: Badges 24/7 actifs (nb) | B40: 1 | C40: 1 | D40: 2 | E40: 3 | F40: 3 | G40: 4 | H40: 4 | I40: 4 | J40: 5 | K40: 5 | L40: 5 | M40: 6
A41: ▶ CA badges (5 €/mois) | B41: =B40*5 -> 5 | C41: =C40*5 -> 5 | D41: =D40*5 -> 10 | E41: =E40*5 -> 15 | F41: =F40*5 -> 15 | G41: =G40*5 -> 20 | H41: =H40*5 -> 20 | I41: =I40*5 -> 20 | ... M41: =M40*5 -> 30 | N41: =SUM(B41:M41) -> 215
A42: Adhésions encaissées / mois (€) | B42: 120 | C42: 60 | D42: 180 | E42: 120 | F42: 120 | G42: 180 | H42: 120 | I42: 60 | J42: 240 | K42: 180 | L42: 180 | M42: 120 | N42: =SUM(B42:M42) -> 1680
A44: ▶▶▶ TOTAL CA HT MENSUEL
A45: CA TOTAL HT | B45: =B8+B9+B25+B28+B34+B39+B41+B42 -> 731.38 | C45: =C8+C9+C25+C28+C34+C39+C41+C42 -> 966.38 | D45: =D8+D9+D25+D28+D34+D39+D41+D42 -> 1875.76 | E45: =E8+E9+E25+E28+E34+E39+E41+E42 -> 1953.76 | F45: =F8+F9+F25+F28+F34+F39+F41+F42 -> 2442.76 | G45: =G8+G9+G25+G28+G34+G39+G41+G42 -> 2951.76 | H45: =H8+H9+H25+H28+H34+H39+H41+H42 -> 2923.14 | I45: =I8+I9+I25+I28+I34+I39+I41+I42 -> 2500.14 | ... M45: =M8+M9+M25+M28+M34+M39+M41+M42 -> 5240.9 | N45: =SUM(B45:M45) -> 35089.92
...

Sheet 💸 Charges
A1: CHARGES D'EXPLOITATION 2026 — DÉTAIL MENSUEL
A2: Sources : Bail IMMO BEAUSOLEIL (1950€/mois + charges 4580€/an) · Hiscox (544,84€/an) · Budget Prévisionnel Trésorerie
A4: 🏠 LOYER DU BAIL COMMERCIAL (IMMO BEAUSOLEIL — Jean-Jacques MAUROU)
A5: Ligne | B5: Jan | C5: Fév | D5: Mar | E5: Avr | F5: Mai | G5: Juin | H5: Juil | I5: Août | J5: Sep | K5: Oct | L5: Nov | M5: Déc | N5: TOTAL
A6: Loyer HC €/mois | B6: 250 | C6: 250 | D6: 250 | E6: 250 | F6: 250 | G6: 250 | H6: 1950 | I6: 1950 | J6: 1950 | K6: 1950 | L6: 1950 | M6: 1950 | N6: =SUM(B6:M6) -> 13200
A8: 💧 CHARGES RÉCUPÉRABLES VERSÉES AU BAILLEUR
A9: Ligne | B9: Jan | C9: Fév | D9: Mar | E9: Avr | F9: Mai | G9: Juin | H9: Juil | I9: Août | J9: Sep | K9: Oct | L9: Nov | M9: Déc | N9: TOTAL
A10: Eau (300 €/an = 25 €/mois) | B10: 25 | C10: 25 | D10: 25 | E10: 25 | F10: 25 | G10: 25 | H10: 25 | I10: 25 | J10: 25 | K10: 25 | L10: 25 | M10: 25 | N10: =SUM(B10:M10) -> 300
A11: Électricité communs (180 €/an = 15 €/mois) | B11: 15 | C11: 15 | D11: 15 | E11: 15 | F11: 15 | G11: 15 | H11: 15 | I11: 15 | J11: 15 | K11: 15 | L11: 15 | M11: 15 | N11: =SUM(B11:M11) -> 180
A12: Taxe foncière 50% (4 200 €/an prov. 350 €/mois) | B12: 350 | C12: 350 | D12: 350 | E12: 350 | F12: 350 | G12: 350 | H12: 350 | I12: 350 | J12: 350 | K12: 350 | L12: 350 | M12: 350 | N12: =SUM(B12:M12) -> 4200
A14: ⚡ FLUIDES & SERVICES PROPRES GÉNIE
A15: Ligne | B15: Jan | C15: Fév | D15: Mar | E15: Avr | F15: Mai | G15: Juin | H15: Juil | I15: Août | J15: Sep | K15: Oct | L15: Nov | M15: Déc | N15: TOTAL
A16: Électricité consommation propre | B16: 200 | C16: 180 | D16: 150 | E16: 100 | F16: 80 | G16: 80 | H16: 80 | I16: 80 | J16: 100 | K16: 150 | L16: 200 | M16: 250 | N16: =SUM(B16:M16) -> 1650
A17: Télécom / Fibre pro | B17: 65 | C17: 65 | D17: 65 | E17: 65 | F17: 65 | G17: 65 | H17: 65 | I17: 65 | J17: 65 | K17: 65 | L17: 65 | M17: 65 | N17: =SUM(B17:M17) -> 780
A18: Ménage / entretien (dès février) | B18: 0 | C18: 100 | D18: 100 | E18: 100 | F18: 100 | G18: 100 | H18: 100 | I18: 100 | J18: 100 | K18: 100 | L18: 100 | M18: 100 | N18: =SUM(B18:M18) -> 1100
A20: 🛡 ASSURANCES (Contrat Hiscox n° HSXIN320075627B)
A21: Ligne | B21: Jan | C21: Fév | D21: Mar | E21: Avr | F21: Mai | G21: Juin | H21: Juil | I21: Août | J21: Sep | K21: Oct | L21: Nov | M21: Déc | N21: TOTAL
A22: Assurance Hiscox (prélèvement mensuel) | B22: 51.38 | C22: 44.86 | D22: 44.86 | E22: 44.86 | F22: 44.86 | G22: 44.86 | H22: 44.86 | I22: 44.86 | J22: 44.86 | K22: 44.86 | L22: 44.86 | M22: 44.86 | N22: =SUM(B22:M22) -> 544.84
A24: 🎪 FONCTIONNEMENT, COMMUNICATION & ANIMATIONS
A25: Ligne | B25: Jan | C25: Fév | D25: Mar | E25: Avr | F25: Mai | G25: Juin | H25: Juil | I25: Août | J25: Sep | K25: Oct | L25: Nov | M25: Déc | N25: TOTAL
A26: Comptabilité / expert-comptable (dès juillet) | B26: 0 | C26: 0 | D26: 0 | E26: 0 | F26: 0 | G26: 0 | H26: 80 | I26: 80 | J26: 80 | K26: 80 | L26: 80 | M26: 80 | N26: =SUM(B26:M26) -> 480
A27: Communication / marketing | B27: 100 | C27: 200 | D27: 200 | E27: 150 | F27: 100 | G27: 50 | H27: 0 | I27: 0 | J27: 100 | K27: 100 | L27: 50 | M27: 50 | N27: =SUM(B27:M27) -> 1100
A28: Animations (4/mois — voir onglet dédié) | B28: ='🎪 Animations'!B18 -> 50 | C28: ='🎪 Animations'!C18 -> 50 | D28: ='🎪 Animations'!D18 -> 100 | E28: ='🎪 Animations'!E18 -> 80 | F28: ='🎪 Animations'!F18 -> 80 | G28: ='🎪 Animations'!G18 -> 80 | H28: ='🎪 Animations'!H18 -> 50 | I28: ='🎪 Animations'!I18 -> 0 | ... M28: ='🎪 Animations'!M18 -> 100 | N28: =SUM(B28:M28) -> 890
A29: Fournitures / consommables | B29: 60 | C29: 60 | D29: 60 | E29: 60 | F29: 60 | G29: 60 | H29: 60 | I29: 60 | J29: 60 | K29: 60 | L29: 60 | M29: 60 | N29: =SUM(B29:M29) -> 720
A30: Divers / imprévus (5%) | B30: 50 | C30: 50 | D30: 50 | E30: 50 | F30: 50 | G30: 50 | H30: 50 | I30: 50 | J30: 50 | K30: 50 | L30: 50 | M30: 50 | N30: =SUM(B30:M30) -> 600
A32: ▶▶▶ TOTAL CHARGES MENSUELLES
A33: TOTAL CHARGES | B33: =B6+B10+B11+B12+B16+B17+B18+B22+B26+B27+B28+B29+B30 -> 1216.38 | C33: =C6+C10+C11+C12+C16+C17+C18+C22+C26+C27+C28+C29+C30 -> 1389.86 | D33: =D6+D10+D11+D12+D16+D17+D18+D22+D26+D27+D28+D29+D30 -> 1409.86 | E33: =E6+E10+E11+E12+E16+E17+E18+E22+E26+E27+E28+E29+E30 -> 1289.86 | F33: =F6+F10+F11+F12+F16+F17+F18+F22+F26+F27+F28+F29+F30 -> 1219.86 | G33: =G6+G10+G11+G12+G16+G17+G18+G22+G26+G27+G28+G29+G30 -> 1169.86 | H33: =H6+H10+H11+H12+H16+H17+H18+H22+H26+H27+H28+H29+H30 -> 2869.86 | I33: =I6+I10+I11+I12+I16+I17+I18+I22+I26+I27+I28+I29+I30 -> 2819.86 | ... M33: =M6+M10+M11+M12+M16+M17+M18+M22+M26+M27+M28+M29+M30 -> 3139.86 | N33: =SUM(B33:M33) -> 25744.84

Sheet 🎪 Animations
A1: PROGRAMMATION & BUDGET DES ANIMATIONS 2026
A2: Source : genie_animations_v2.docx + genie_suivi_animations.xlsx · Rythme cible : 1 animation par semaine (4/mois)
A4: 📋 CATALOGUE DES FORMATS D'ANIMATION
A5: Format | B5: Fréquence cible | C5: Jauge | D5: Durée | E5: Budget unitaire | F5: Levier d'optimisation
A6: ☕ Petit Déjeuner Entrepreneurs | B6: Hebdo S1 | C6: 10-20 | D6: 1h | E6: 45 | F6: Partenariat boulangerie locale → -20 €
A7: 🍹 Afterwork décontracté | B7: Mensuel S3 | C7: 15-30 | D7: 2h | E7: 45 | F7: Modèle participatif (apports) → budget 20 €
A8: 🤖 Atelier IA en entreprise | B8: Trimestriel | C8: 12-25 | D8: 1h | E8: 105 | F8: Samir anime en interne (CCFA) → 25 €
A9: ₿ Initiation Cryptomonnaie | B9: Trimestriel | C9: 12-25 | D9: 1h15 | E9: 105 | F9: Intervenant vulgarisateur externe
A10: 📍 Atelier Business Local | B10: Bimestriel S4 | C10: 10-20 | D10: 1h30 | E10: 100 | F10: Témoin invité = ambassadeur Génie
A11: 🌿 Bien-être indépendant | B11: Trimestriel | C11: 8-15 | D11: 1h30 | E11: 30 | F11: Déjeuner participatif — facilitateur bénévole
A14: 📅 BUDGET MENSUEL DES ANIMATIONS (rythme 4/mois)
A15: Ligne | B15: Jan | C15: Fév | D15: Mar | E15: Avr | F15: Mai | G15: Juin | H15: Juil | I15: Août | J15: Sep | K15: Oct | L15: Nov | M15: Déc | N15: TOTAL
A16: Budget prévu / semaine × 4 | B16: 50 | C16: 50 | D16: 100 | E16: 80 | F16: 80 | G16: 80 | H16: 50 | I16: 0 | J16: 100 | K16: 100 | L16: 100 | M16: 100 | N16: =SUM(B16:M16) -> 890
A17: Commentaire mois | B17: Démarrage léger | I17: Pause estivale | J17: Reprise
A18: TOTAL Animations mensuel | B18: =B16 -> 50 | C18: =C16 -> 50 | D18: =D16 -> 100 | E18: =E16 -> 80 | F18: =F16 -> 80 | G18: =G16 -> 80 | H18: =H16 -> 50 | I18: =I16 -> 0 | ... M18: =M16 -> 100 | N18: =SUM(B18:M18) -> 890
A20: 🗓 PLANNING-TYPE MENSUEL
A21: S1 Mardi matin 08h30-09h30 | D21: ☕ Petit Déjeuner des Entrepreneurs
A22: S2 Jeudi soir 18h30-19h30 | D22: 🤖 Atelier IA / ₿ Atelier Crypto (alternance)
A23: S3 Jeudi soir 19h00-21h00 | D23: 🍹 Afterwork décontracté
A24: S4 Mardi après-midi 14h00-15h30 | D24: 📍 Atelier Business Local / 🌿 Bien-être

Sheet 📈 Compte de résultat
A1: COMPTE DE RÉSULTAT PRÉVISIONNEL 2026
A2: Vue consolidée revenus — charges = résultat net mensuel · seuil de rentabilité identifié
A4: ▶ REVENUS (liens vers onglet 💰 Revenus)
A5: Ligne | B5: Jan | C5: Fév | D5: Mar | E5: Avr | F5: Mai | G5: Juin | H5: Juil | I5: Août | J5: Sep | K5: Oct | L5: Nov | M5: Déc | N5: TOTAL
A6: Bureaux privatifs (loyer HC) | B6: ='💰 Revenus'!B8 -> 306 | C6: ='💰 Revenus'!C8 -> 306 | D6: ='💰 Revenus'!D8 -> 612 | E6: ='💰 Revenus'!E8 -> 612 | F6: ='💰 Revenus'!F8 -> 612 | G6: ='💰 Revenus'!G8 -> 612 | H6: ='💰 Revenus'!H8 -> 918 | I6: ='💰 Revenus'!I8 -> 918 | ... M6: ='💰 Revenus'!M8 -> 1530 | N6: =SUM(B6:M6) -> 10404
A7: Charges refacturées locataires | B7: ='💰 Revenus'!B9 -> 70.38 | C7: ='💰 Revenus'!C9 -> 70.38 | D7: ='💰 Revenus'!D9 -> 140.76 | E7: ='💰 Revenus'!E9 -> 140.76 | F7: ='💰 Revenus'!F9 -> 140.76 | G7: ='💰 Revenus'!G9 -> 140.76 | H7: ='💰 Revenus'!H9 -> 211.14 | I7: ='💰 Revenus'!I9 -> 211.14 | ... M7: ='💰 Revenus'!M9 -> 351.9 | N7: =SUM(B7:M7) -> 2392.92
A8: Coworking — journée | B8: ='💰 Revenus'!B18 -> 0 | C8: ='💰 Revenus'!C18 -> 0 | D8: ='💰 Revenus'!D18 -> 0 | E8: ='💰 Revenus'!E18 -> 0 | F8: ='💰 Revenus'!F18 -> 0 | G8: ='💰 Revenus'!G18 -> 0 | H8: ='💰 Revenus'!H18 -> 637.3 | I8: ='💰 Revenus'!I18 -> 637.3 | ... M8: ='💰 Revenus'!M18 -> 637.3 | N8: =SUM(B8:M8) -> 3823.8
A9: Coworking — abonnements | B9: ='💰 Revenus'!B21 -> 0 | C9: ='💰 Revenus'!C21 -> 0 | D9: ='💰 Revenus'!D21 -> 0 | E9: ='💰 Revenus'!E21 -> 0 | F9: ='💰 Revenus'!F21 -> 0 | G9: ='💰 Revenus'!G21 -> 0 | H9: ='💰 Revenus'!H21 -> 0 | I9: ='💰 Revenus'!I21 -> 0 | ... M9: ='💰 Revenus'!M21 -> 0 | N9: =SUM(B9:M9) -> 0
A10: Salles de réunion | B10: ='💰 Revenus'!B27 -> 180 | C10: ='💰 Revenus'!C27 -> 180 | D10: ='💰 Revenus'!D27 -> 180 | E10: ='💰 Revenus'!E27 -> 180 | F10: ='💰 Revenus'!F27 -> 180 | G10: ='💰 Revenus'!G27 -> 180 | H10: ='💰 Revenus'!H27 -> 180 | I10: ='💰 Revenus'!I27 -> 180 | ... M10: ='💰 Revenus'!M27 -> 180 | N10: =SUM(B10:M10) -> 2160
A11: Domiciliation | B11: ='💰 Revenus'!B32 -> 2 | C11: ='💰 Revenus'!C32 -> 3 | D11: ='💰 Revenus'!D32 -> 4 | E11: ='💰 Revenus'!E32 -> 3 | F11: ='💰 Revenus'!F32 -> 5 | G11: ='💰 Revenus'!G32 -> 7 | H11: ='💰 Revenus'!H32 -> 4 | I11: ='💰 Revenus'!I32 -> 3 | ... M11: ='💰 Revenus'!M32 -> 9 | N11: =SUM(B11:M11) -> 64
A12: Badges 24/7 | B12: ='💰 Revenus'!B34 -> 230 | C12: ='💰 Revenus'!C34 -> 345 | D12: ='💰 Revenus'!D34 -> 460 | E12: ='💰 Revenus'!E34 -> 345 | F12: ='💰 Revenus'!F34 -> 575 | G12: ='💰 Revenus'!G34 -> 805 | H12: ='💰 Revenus'!H34 -> 460 | I12: ='💰 Revenus'!I34 -> 345 | ... M12: ='💰 Revenus'!M34 -> 1035 | N12: =SUM(B12:M12) -> 7360
A13: Adhésions association | B13: ='💰 Revenus'!B35 -> 0 | C13: ='💰 Revenus'!C35 -> 0 | D13: ='💰 Revenus'!D35 -> 0 | E13: ='💰 Revenus'!E35 -> 0 | F13: ='💰 Revenus'!F35 -> 0 | G13: ='💰 Revenus'!G35 -> 0 | H13: ='💰 Revenus'!H35 -> 0 | I13: ='💰 Revenus'!I35 -> 0 | ... M13: ='💰 Revenus'!M35 -> 0 | N13: =SUM(B13:M13) -> 0
A15: TOTAL CA HT | B15: =SUM(B6:B14) -> 788.38 | C15: =SUM(C6:C14) -> 904.38 | D15: =SUM(D6:D14) -> 1396.76 | E15: =SUM(E6:E14) -> 1280.76 | F15: =SUM(F6:F14) -> 1512.76 | G15: =SUM(G6:G14) -> 1744.76 | H15: =SUM(H6:H14) -> 2410.44 | I15: =SUM(I6:I14) -> 2294.44 | ... N15: =SUM(N6:N14) -> 26204.72
A17: ▶ CONTRÔLE CA vs onglet Revenus | B17: ='💰 Revenus'!B38 -> 0 | C17: ='💰 Revenus'!C38 -> 0 | D17: ='💰 Revenus'!D38 -> 1 | E17: ='💰 Revenus'!E38 -> 1 | F17: ='💰 Revenus'!F38 -> 2 | G17: ='💰 Revenus'!G38 -> 2 | H17: ='💰 Revenus'!H38 -> 2 | I17: ='💰 Revenus'!I38 -> 2 | ... M17: ='💰 Revenus'!M38 -> 4 | N17: ='💰 Revenus'!N45 -> 35089.92
A19: CA TOTAL (cellule de référence synthèse) | B19: =B15 -> 788.38 | C19: =C15 -> 904.38 | D19: =D15 -> 1396.76 | E19: =E15 -> 1280.76 | F19: =F15 -> 1512.76 | G19: =G15 -> 1744.76 | H19: =H15 -> 2410.44 | I19: =I15 -> 2294.44 | ... N19: =N15 -> 26204.72
A21: ▶ CHARGES (liens vers onglet 💸 Charges)
A22: Ligne | B22: Jan | C22: Fév | D22: Mar | E22: Avr | F22: Mai | G22: Juin | H22: Juil | I22: Août | J22: Sep | K22: Oct | L22: Nov | M22: Déc | N22: TOTAL
A23: Loyer IMMO Beausoleil | B23: ='💸 Charges'!B6 -> 250 | C23: ='💸 Charges'!C6 -> 250 | D23: ='💸 Charges'!D6 -> 250 | E23: ='💸 Charges'!E6 -> 250 | F23: ='💸 Charges'!F6 -> 250 | G23: ='💸 Charges'!G6 -> 250 | H23: ='💸 Charges'!H6 -> 1950 | I23: ='💸 Charges'!I6 -> 1950 | ... M23: ='💸 Charges'!M6 -> 1950 | N23: =SUM(B23:M23) -> 13200
A24: Eau (provision bailleur) | B24: ='💸 Charges'!B10 -> 25 | C24: ='💸 Charges'!C10 -> 25 | D24: ='💸 Charges'!D10 -> 25 | E24: ='💸 Charges'!E10 -> 25 | F24: ='💸 Charges'!F10 -> 25 | G24: ='💸 Charges'!G10 -> 25 | H24: ='💸 Charges'!H10 -> 25 | I24: ='💸 Charges'!I10 -> 25 | ... M24: ='💸 Charges'!M10 -> 25 | N24: =SUM(B24:M24) -> 300
A25: Électricité communs (bailleur) | B25: ='💸 Charges'!B11 -> 15 | C25: ='💸 Charges'!C11 -> 15 | D25: ='💸 Charges'!D11 -> 15 | E25: ='💸 Charges'!E11 -> 15 | F25: ='💸 Charges'!F11 -> 15 | G25: ='💸 Charges'!G11 -> 15 | H25: ='💸 Charges'!H11 -> 15 | I25: ='💸 Charges'!I11 -> 15 | ... M25: ='💸 Charges'!M11 -> 15 | N25: =SUM(B25:M25) -> 180
A26: Taxe foncière (provision) | B26: ='💸 Charges'!B12 -> 350 | C26: ='💸 Charges'!C12 -> 350 | D26: ='💸 Charges'!D12 -> 350 | E26: ='💸 Charges'!E12 -> 350 | F26: ='💸 Charges'!F12 -> 350 | G26: ='💸 Charges'!G12 -> 350 | H26: ='💸 Charges'!H12 -> 350 | I26: ='💸 Charges'!I12 -> 350 | ... M26: ='💸 Charges'!M12 -> 350 | N26: =SUM(B26:M26) -> 4200
A27: Électricité propre Génie | B27: ='💸 Charges'!B16 -> 200 | C27: ='💸 Charges'!C16 -> 180 | D27: ='💸 Charges'!D16 -> 150 | E27: ='💸 Charges'!E16 -> 100 | F27: ='💸 Charges'!F16 -> 80 | G27: ='💸 Charges'!G16 -> 80 | H27: ='💸 Charges'!H16 -> 80 | I27: ='💸 Charges'!I16 -> 80 | ... M27: ='💸 Charges'!M16 -> 250 | N27: =SUM(B27:M27) -> 1650
A28: Télécom / fibre | B28: ='💸 Charges'!B17 -> 65 | C28: ='💸 Charges'!C17 -> 65 | D28: ='💸 Charges'!D17 -> 65 | E28: ='💸 Charges'!E17 -> 65 | F28: ='💸 Charges'!F17 -> 65 | G28: ='💸 Charges'!G17 -> 65 | H28: ='💸 Charges'!H17 -> 65 | I28: ='💸 Charges'!I17 -> 65 | ... M28: ='💸 Charges'!M17 -> 65 | N28: =SUM(B28:M28) -> 780
A29: Ménage / entretien | B29: ='💸 Charges'!B18 -> 0 | C29: ='💸 Charges'!C18 -> 100 | D29: ='💸 Charges'!D18 -> 100 | E29: ='💸 Charges'!E18 -> 100 | F29: ='💸 Charges'!F18 -> 100 | G29: ='💸 Charges'!G18 -> 100 | H29: ='💸 Charges'!H18 -> 100 | I29: ='💸 Charges'!I18 -> 100 | ... M29: ='💸 Charges'!M18 -> 100 | N29: =SUM(B29:M29) -> 1100
A30: Assurance Hiscox | B30: ='💸 Charges'!B22 -> 51.38 | C30: ='💸 Charges'!C22 -> 44.86 | D30: ='💸 Charges'!D22 -> 44.86 | E30: ='💸 Charges'!E22 -> 44.86 | F30: ='💸 Charges'!F22 -> 44.86 | G30: ='💸 Charges'!G22 -> 44.86 | H30: ='💸 Charges'!H22 -> 44.86 | I30: ='💸 Charges'!I22 -> 44.86 | ... M30: ='💸 Charges'!M22 -> 44.86 | N30: =SUM(B30:M30) -> 544.84
A31: Expert-comptable | B31: ='💸 Charges'!B26 -> 0 | C31: ='💸 Charges'!C26 -> 0 | D31: ='💸 Charges'!D26 -> 0 | E31: ='💸 Charges'!E26 -> 0 | F31: ='💸 Charges'!F26 -> 0 | G31: ='💸 Charges'!G26 -> 0 | H31: ='💸 Charges'!H26 -> 80 | I31: ='💸 Charges'!I26 -> 80 | ... M31: ='💸 Charges'!M26 -> 80 | N31: =SUM(B31:M31) -> 480
A32: Communication / marketing | B32: ='💸 Charges'!B27 -> 100 | C32: ='💸 Charges'!C27 -> 200 | D32: ='💸 Charges'!D27 -> 200 | E32: ='💸 Charges'!E27 -> 150 | F32: ='💸 Charges'!F27 -> 100 | G32: ='💸 Charges'!G27 -> 50 | H32: ='💸 Charges'!H27 -> 0 | I32: ='💸 Charges'!I27 -> 0 | ... M32: ='💸 Charges'!M27 -> 50 | N32: =SUM(B32:M32) -> 1100
A33: TOTAL CHARGES (réf synthèse) | B33: =B36 -> 1116.38 | C33: =C36 -> 1289.86 | D33: =D36 -> 1259.86 | E33: =E36 -> 1159.86 | F33: =F36 -> 1089.86 | G33: =G36 -> 1039.86 | H33: =H36 -> 2769.86 | I33: =I36 -> 2769.86 | ... N33: =N36 -> 24254.84
A34: Fournitures / consommables | B34: ='💸 Charges'!B29 -> 60 | C34: ='💸 Charges'!C29 -> 60 | D34: ='💸 Charges'!D29 -> 60 | E34: ='💸 Charges'!E29 -> 60 | F34: ='💸 Charges'!F29 -> 60 | G34: ='💸 Charges'!G29 -> 60 | H34: ='💸 Charges'!H29 -> 60 | I34: ='💸 Charges'!I29 -> 60 | ... M34: ='💸 Charges'!M29 -> 60 | N34: =SUM(B34:M34) -> 720
A35: ★ RÉSULTAT NET MENSUEL | B35: =B19-B33 -> -328 | C35: =C19-C33 -> -385.48 | D35: =D19-D33 -> 136.9 | E35: =E19-E33 -> 120.9 | F35: =F19-F33 -> 422.9 | G35: =G19-G33 -> 704.9 | H35: =H19-H33 -> -359.42 | I35: =I19-I33 -> -475.42 | ... N35: =N19-N33 -> 1949.88
A36: TOTAL CHARGES | B36: =SUM(B23:B32)+B34 -> 1116.38 | C36: =SUM(C23:C32)+C34 -> 1289.86 | D36: =SUM(D23:D32)+D34 -> 1259.86 | E36: =SUM(E23:E32)+E34 -> 1159.86 | F36: =SUM(F23:F32)+F34 -> 1089.86 | G36: =SUM(G23:G32)+G34 -> 1039.86 | H36: =SUM(H23:H32)+H34 -> 2769.86 | I36: =SUM(I23:I32)+I34 -> 2769.86 | ... N36: =SUM(N23:N32)+N34 -> 24254.84
A37: ⚖ SEUIL DE RENTABILITÉ mensuel (charges fixes hors anim/comm) | B37: =AVERAGE(H36:M36) -> 2883.1933 | C37: → CA mensuel minimum à atteindre pour équilibrer les charges (juillet à décembre)

Sheet 💧 Trésorerie
A1: TRÉSORERIE PRÉVISIONNELLE 2026
A2: Flux de trésorerie cumulé · apport initial + avance CCFA · Alerte si solde < seuil sécurité
A4: 💰 FLUX DE TRÉSORERIE MENSUEL
A5: Ligne | B5: Jan | C5: Fév | D5: Mar | E5: Avr | F5: Mai | G5: Juin | H5: Juil | I5: Août | J5: Sep | K5: Oct | L5: Nov | M5: Déc | N5: TOTAL
A6: Trésorerie début de mois | B6: 500 | C6: =B13 -> 7383.62 | D6: =C13 -> 6093.76 | E6: =D13 -> 5333.9 | F6: =E13 -> 4674.04 | G6: =F13 -> 4084.18 | H6: =G13 -> 3544.32 | I6: =H13 -> 1974.46 | J6: =I13 -> 404.6 | ... M6: =L13 -> -3964.98
A7: + Encaissements CA du mois | B7: 0 | C7: 0 | D7: 500 | E7: 500 | F7: 500 | G7: 500 | H7: 1200 | I7: 1200 | J7: 1300 | K7: 1300 | L7: 1800 | M7: 2000 | N7: =SUM(B7:M7) -> 10800
A8: + Avance CCFA (convention à formaliser, max 10k€) | B8: 8000 | C8: 0 | D8: 0 | E8: 0 | F8: 0 | G8: 0 | H8: 0 | I8: 0 | J8: 0 | K8: 0 | L8: 0 | M8: 0 | N8: =SUM(B8:M8) -> 8000
A9: + Apport / subvention (à préciser) | B9: 0 | C9: 0 | D9: 0 | E9: 0 | F9: 0 | G9: 0 | H9: 0 | I9: 0 | J9: 0 | K9: 0 | L9: 0 | M9: 0 | N9: =SUM(B9:M9) -> 0
A10: – Décaissements charges du mois | B10: =-'📈 Compte de résultat'!B33 -> -1116.38 | C10: =-'📈 Compte de résultat'!C33 -> -1289.86 | D10: =-'📈 Compte de résultat'!D33 -> -1259.86 | E10: =-'📈 Compte de résultat'!E33 -> -1159.86 | F10: =-'📈 Compte de résultat'!F33 -> -1089.86 | G10: =-'📈 Compte de résultat'!G33 -> -1039.86 | H10: =-'📈 Compte de résultat'!H33 -> -2769.86 | I10: =-'📈 Compte de résultat'!I33 -> -2769.86 | ... M10: =-'📈 Compte de résultat'!M33 -> -2989.86 | N10: =SUM(B10:M10) -> -24254.84
A12: FLUX NET DU MOIS | B12: =B7+B8+B9+B10 -> 6883.62 | C12: =C7+C8+C9+C10 -> -1289.86 | D12: =D7+D8+D9+D10 -> -759.86 | E12: =E7+E8+E9+E10 -> -659.86 | F12: =F7+F8+F9+F10 -> -589.86 | G12: =G7+G8+G9+G10 -> -539.86 | H12: =H7+H8+H9+H10 -> -1569.86 | I12: =I7+I8+I9+I10 -> -1569.86 | ... M12: =M7+M8+M9+M10 -> -989.86 | N12: =SUM(B12:M12) -> -5454.84
A13: TRÉSORERIE FIN DE MOIS (solde cumulé) | B13: =B6+B12 -> 7383.62 | C13: =C6+C12 -> 6093.76 | D13: =D6+D12 -> 5333.9 | E13: =E6+E12 -> 4674.04 | F13: =F6+F12 -> 4084.18 | G13: =G6+G12 -> 3544.32 | H13: =H6+H12 -> 1974.46 | I13: =I6+I12 -> 404.6 | ... M13: =M6+M12 -> -4954.84 | N13: =M13 -> -4954.84
A15: Mois le + bas de l'année :
A16: Solde minimum atteint | C16: =MIN(B13:M13) -> -4954.84 | F16: Mois concerné : | I16: =INDEX($B$5:$M$5,MATCH(MIN(B13:M13),B13:M13,0)) -> Déc

Sheet 🎯 Scenarios
A1: SCÉNARIOS DE REMPLISSAGE 2026 — BAS / MÉDIAN / HAUT
A2: Modélisation à 3 hypothèses · le scénario médian correspond à l'onglet 💰 Revenus
A4: ⚙️ HYPOTHÈSES PAR SCÉNARIO (annuelles moyennes)
A5: Paramètre | C5: 🔴 BAS | E5: 🟡 MÉDIAN | G5: 🟢 HAUT
A6: Taux d'occupation bureaux privatifs | B6: (moyenne 2026) | C6: 0.25 | E6: 0.4 | G6: 0.6
A7: Nb bureaux occupés (sur 8) | C7: =C6*8 -> 2 | E7: =E6*8 -> 3.2 | G7: =G6*8 -> 4.8
A8: Coworking — abonnements actifs / mois | C8: 2 | E8: 5 | G8: 10
A9: Coworking — passages journée / mois | C9: 5 | E9: 11 | G9: 20
A10: Salles — réservations / mois | C10: 3 | E10: 6 | G10: 10
A11: Domiciliations actives | C11: 1 | E11: 3 | G11: 6
A12: Badges 24/7 actifs | C12: 2 | E12: 4 | G12: 7
A13: Adhésions / an (moy.) | C13: 20 | E13: 30 | G13: 45
A16: 💰 CHIFFRE D'AFFAIRES ANNUEL 2026 PAR SCÉNARIO
A17: Poste | C17: BAS | E17: MÉDIAN | G17: HAUT
A18: CA bureaux privatifs | C18: =C6*29376 -> 7344 | E18: =E6*29376 -> 11750.4 | G18: =G6*29376 -> 17625.6
A19: Charges refacturées (23%) | C19: =C18*0.23 -> 1689.12 | E19: =E18*0.23 -> 2702.592 | G19: =G18*0.23 -> 4053.888
A20: Coworking — abonnements | C20: =C8*180*12 -> 4320 | E20: =E8*180*12 -> 10800 | G20: =G8*180*12 -> 21600
A21: Coworking — journées | C21: =C9*17*12 -> 1020 | E21: =E9*17*12 -> 2244 | G21: =G9*17*12 -> 4080
A22: Salles de réunion | C22: =C10*115*12 -> 4140 | E22: =E10*115*12 -> 8280 | G22: =G10*115*12 -> 13800
A23: Domiciliation | C23: =C11*45*12 -> 540 | E23: =E11*45*12 -> 1620 | G23: =G11*45*12 -> 3240
A24: Badges 24/7 | C24: =C12*5*12 -> 120 | E24: =E12*5*12 -> 240 | G24: =G12*5*12 -> 420
A25: Adhésions (tarif moyen 55 €) | C25: =C13*55 -> 1100 | E25: =E13*55 -> 1650 | G25: =G13*55 -> 2475
A27: CA TOTAL ANNUEL | C27: =SUM(C18:C25) -> 20273.12 | E27: =SUM(E18:E25) -> 39286.992 | G27: =SUM(G18:G25) -> 67294.488
A28: CHARGES TOTALES | C28: ='📈 Compte de résultat'!N33*0.95 -> 23042.098 | E28: ='📈 Compte de résultat'!N33*1 -> 24254.84 | G28: ='📈 Compte de résultat'!N33*1.08 -> 26195.227
A29: ★ RÉSULTAT NET 2026 | C29: =C27-C28 -> -2768.978 | E29: =E27-E28 -> 15032.152 | G29: =G27-G28 -> 41099.261
A31: 🧭 LECTURE OPÉRATIONNELLE DES SCÉNARIOS
A32: 🔴 BAS | B32: Si rien ne démarre vraiment (2 bureaux sur 8, peu de cowork, 3 salles/mois) | E32: Déficit > 8 k€ — MOBILISER subventions + avance CCFA 10 k€ + ralentir les investissements
A33: 🟡 MÉDIAN | B33: Rythme réaliste (3-4 bureaux sur 8, 5 abonnements cowork, 6 salles/mois) | E33: Résultat proche équilibre — tenir le CAP sur la prospection bureau avant juillet
A34: 🟢 HAUT | B34: Montée en puissance forte (5-6 bureaux sur 8, 10 abonnements, 10 salles/mois) | E34: Excédent à réinvestir (équipement, salarié à temps partiel, fonds de réserve)
A36: ⚖️ POINT MORT — CA MENSUEL NÉCESSAIRE POUR ÉQUILIBRER LES CHARGES
A37: Charges fixes moyennes mensuelles (juil-déc) | E37: ='📈 Compte de résultat'!B37 -> 2883.1933
A38: → Équivalent ~ nb de bureaux occupés (tarif 1 an, moy. 306 €/mois) | E38: =E37/306 -> 9.4222004
A39: → Ou ~ nb d'abonnements cowork (180 €/mois) | E39: =E37/180 -> 16.017741
A40: → Ou combinaison : 3 bureaux + 3 abo cowork + 5 salles + 4 domiciliations

Sheet 📅 Projection 2027
A1: PROJECTION 2027 — ANNÉE 2 DU TIERS-LIEU
A2: Hypothèse : maturité commerciale + levée d'une subvention · révision annuelle loyer (ILC ~ +3%)
A4: 📊 PROJECTION 2027 vs RÉALISÉ / PRÉVU 2026
A5: Poste | B5: Hypothèse 2027 | C5: 2026 (prév.) | D5: 2027 (proj.) | E5: Évolution | H5: Commentaire
A6: ▶ REVENUS
A7: Bureaux privatifs (loyer HC) | B7: Taux occ. 0.60 (an 2) | C7: ='📈 Compte de résultat'!N6 -> 10404 | D7: ='📈 Compte de résultat'!N6*1.65 -> 17166.6 | E7: =IFERROR((D7-C7)/C7,"—") -> 0.65 | F7: Objectif : 5 bureaux sur 8 occupés en moyenne annuelle
A8: Charges refacturées (23%) | B8: Idem montée en charge | C8: ='📈 Compte de résultat'!N7 -> 2392.92 | D8: =D7*0.23 -> 3948.318 | E8: =IFERROR((D8-C8)/C8,"—") -> 0.65 | F8: Proportionnel au loyer HC
A9: Coworking — journées | B9: Doublement passages | C9: ='📈 Compte de résultat'!N8 -> 3823.8 | D9: ='📈 Compte de résultat'!N8*2 -> 7647.6 | E9: =IFERROR((D9-C9)/C9,"—") -> 1 | F9: Effet bouche-à-oreille après an 1
A10: Coworking — abonnements | B10: Doublement abonnés | C10: ='📈 Compte de résultat'!N9 -> 0 | D10: ='📈 Compte de résultat'!N9*2 -> 0 | E10: =IFERROR((D10-C10)/C10,"—") -> — | F10: Objectif 10 abonnés actifs
A11: Salles de réunion | B11: +50% fréquentation | C11: ='📈 Compte de résultat'!N10 -> 2160 | D11: ='📈 Compte de résultat'!N10*1.5 -> 3240 | E11: =IFERROR((D11-C11)/C11,"—") -> 0.5 | F11: Programmation renforcée + partenariats
A12: Domiciliation | B12: Doublement | C12: ='📈 Compte de résultat'!N11 -> 64 | D12: ='📈 Compte de résultat'!N11*2 -> 128 | E12: =IFERROR((D12-C12)/C12,"—") -> 1 | F12: Cible : 8 entreprises domiciliées
A13: Badges 24/7 | B13: +50% | C13: ='📈 Compte de résultat'!N12 -> 7360 | D13: ='📈 Compte de résultat'!N12*1.5 -> 11040 | E13: =IFERROR((D13-C13)/C13,"—") -> 0.5
A14: Adhésions | B14: +30% membres | C14: ='📈 Compte de résultat'!N13 -> 0 | D14: ='📈 Compte de résultat'!N13*1.3 -> 0 | E14: =IFERROR((D14-C14)/C14,"—") -> — | F14: Conversion des utilisateurs ponctuels
A15: Subvention (FDVA / Région / DLA) | B15: Dépôt dossier 2026 | C15: 0 | D15: 5000 | E15: =IFERROR((D15-C15)/C15,"—") -> — | F15: Objectif : 5 k€ via FDVA ou aide régionale Tiers-Lieux
A17: TOTAL CA 2027 | C17: =SUM(C7:C15) -> 26204.72 | D17: =SUM(D7:D15) -> 48170.518 | E17: =IFERROR((D17-C17)/C17,"—") -> 0.83823823
A19: ▶ CHARGES 2027
A20: Loyer annuel (12 × 1 950 €, plus de remise) | B20: Plein tarif 12 mois | C20: ='📈 Compte de résultat'!N23 -> 13200 | D20: 23400 | E20: Fin de la remise du 1er semestre 2026
A21: Charges récupérables (eau + élec + TF) | B21: Idem bail | C21: =SUM('📈 Compte de résultat'!N24:N26) -> 4680 | D21: 4580 | E21: Stables selon bail
A22: Fluides & services propres | B22: Consommation stable | C22: =SUM('📈 Compte de résultat'!N27:N29) -> 3530 | D22: =C21*1.02 -> 4773.6 | E22: Indexation énergie ~+2%
A23: Assurance Hiscox | B23: Reconduction contrat | C23: ='📈 Compte de résultat'!N30 -> 544.84 | D23: =C22*1.03 -> 3635.9 | E23: Indexation annuelle ~+3%
A24: Expert-comptable | B24: 12 mois vs 6 mois en 2026 | C24: ='📈 Compte de résultat'!N31 -> 480 | D24: =C23*2 -> 1089.68 | E24: Année pleine
A25: Communication / marketing | B25: Baisse après lancement | C25: ='📈 Compte de résultat'!N32 -> 1100 | D25: =C24*0.8 -> 384 | E25: Moins de campagnes de lancement
A26: Animations | B26: Rythme stable | C26: ='📈 Compte de résultat'!N33 -> 24254.84 | D26: ='📈 Compte de résultat'!N33 -> 24254.84 | E26: Programmation stabilisée
A27: Fournitures | B27: Idem | C27: ='📈 Compte de résultat'!N34 -> 720 | D27: =C26*1.05 -> 25467.582 | E27: Volume usagers en hausse
A28: Divers / imprévus | B28: +5% prudentiel | C28: ='📈 Compte de résultat'!N35 -> 1949.88 | D28: =C27*1.05 -> 756
A29: TOTAL CHARGES 2027 | C29: =SUM(C20:C28) -> 50459.56 | D29: =SUM(D20:D28) -> 88341.602
A31: ★ RÉSULTAT NET 2027 | C31: =C17-C29 -> -24254.84 | D31: =D17-D29 -> -40171.084 | E31: =IFERROR((D31-C31)/ABS(C31),"—") -> -0.65620899
A33: 🎯 TRAJECTOIRE À 3 ANS — VISION STRATÉGIQUE
A34: Période | B34: Phase | C34: Hypothèse clé | D34: CA HT | E34: Charges | F34: Résultat
A35: An 1 — 2026 | B35: Lancement | C35: Taux occ. 36% | D35: ='📈 Compte de résultat'!N19 -> 26204.72 | E35: ='📈 Compte de résultat'!N33 -> 24254.84 | F35: ='📈 Compte de résultat'!N35 -> 1949.88
A36: An 2 — 2027 | B36: Consolidation | C36: Taux occ. 60% | D36: =D17 -> 48170.518 | E36: =D29 -> 88341.602 | F36: =D31 -> -40171.084
A37: An 3 — 2028 | B37: Maturité | C37: Taux occ. 75% | D37: =D17*1.25 -> 60213.147 | E37: =D29*1.05 -> 92758.682 | F37: =D36-E36 -> -40171.084

Sheet 📋 Sources
A1: SOURCES, HYPOTHÈSES & MODE D'EMPLOI
A2: Traçabilité complète des données utilisées dans ce budget · Mise à jour 20/04/2026
A4: 🎨 LÉGENDE DES COULEURS
A5: Texte BLEU sur fond JAUNE PÂLE | B5: Saisie manuelle / valeur modifiable par vous
A6: Texte VERT | B6: Lien entre onglets du même classeur — ne pas modifier manuellement
A7: Texte NOIR | B7: Formule de calcul automatique
A8: Fond JAUNE VIF | B8: Cellule stratégique à surveiller
A9: Fond GRIS CLAIR | B9: Total / synthèse automatique
A10: Fond ORANGE/SAUMON | B10: Résultat net ou indicateur clé
A13: 📂 SOURCES DOCUMENTAIRES (fichiers du dossier GENIE)
A14: Onglet | B14: Source | C14: Date | D14: Usage
A15: ⚙️ Hypothèses | B15: Grille tarifaire Génie-Bon-définitif.pdf (racine GENIE) | C15: Avril 2026 | D15: Tarifs officiels 2026 (bureaux, cowork, salles, services)
A16: ⚙️ Hypothèses | B16: Fiche_Adhesion_GENIE_2026_bon-der.docx (racine GENIE) | C16: Avril 2026 | D16: Barèmes adhésion (particulier, asso, entreprise)
A17: 👥 Locataires | B17: Contrat_Bureau_Privatif_Genie-OVNI.docx | C17: 18/03/2026 | D17: Locataire signé : OVNI-Graphics (Bureau 1-09)
A18: 👥 Locataires | B18: 02 - Commercial/Contrats clients en cours/antre-connaissance/ | C18: 2025-2026 | D18: Dossier en constitution
A19: 👥 Locataires | B19: 02 - Commercial/Contrats clients en cours/FNE/ | C19: 2026 | D19: Convention de partenariat
A20: 💸 Charges | B20: Bail IMMO BEAUSOLEIL-Samir CHIKHI.pdf | C20: 2026 | D20: Loyer 1 950 €/mois (remise -1 700 €/mois de janv à juin)
A21: 💸 Charges | B21: Bail IMMO BEAUSOLEIL-Samir CHIKHI.pdf | C21: 2026 | D21: Charges récupérables : eau 300 €/an + élec communs 180 €/an + TF 4 200 €/an
A22: 💸 Charges | B22: Hiscox - Appel de prime.pdf | C22: 07/01/2026 | D22: Assurance Pro by Hiscox : 544,84 €/an
A23: 🎪 Animations | B23: genie_animations_v2.docx | C23: 2026 | D23: Catalogue des formats + budgets unitaires
A24: 🎪 Animations | B24: genie_suivi_animations.xlsx | C24: 2026 | D24: Planning opérationnel par semaine
A25: 💰 Revenus | B25: Previsionnel_Revise_Genie_An1-30-03-26.xlsx | C25: 30/03/2026 | D25: Hypothèses de taux d'occupation et tarifs révisés
... A27: 💧 Trésorerie | B27: Previsionnel_Revise_Genie_An1-30-03-26.xlsx | C27: 30/03/2026 | D27: Avance CCFA 8 000 € + trésorerie initiale 500 €
A30: ⚠ HYPOTHÈSES À ACTUALISER RÉGULIÈREMENT
A31: Hypothèse | B31: Localisation | C31: Règle de mise à jour
A32: Taux d'occupation bureaux | B32: 💰 Revenus lignes 6 | C32: Mettre à jour chaque fin de mois avec le nb réel de bureaux loués
A33: Tarif horaire salles | B33: ⚙️ Hypothèses lignes 25-36 | C33: Vérifier l'alignement avec la grille tarifaire définitive après chaque modif
A34: Charges bailleur | B34: 💸 Charges lignes 10-12 | C34: Régulariser avec le bailleur après appels de TF (octobre) et de charges (décembre)
A35: Budget animations | B35: 🎪 Animations ligne 16 | C35: Ajuster selon le partenariat boulangerie et l'implication des intervenants internes
A36: Avance CCFA | B36: 💧 Trésorerie ligne 8 | C36: Formaliser la convention CCFA → Génie (max 10 000 € — taux légal 5,07%)
A39: 🧭 MODE D'EMPLOI HEBDOMADAIRE & MENSUEL
A40: 🗓 Chaque lundi (30 min) | B40: Mettre à jour le nombre de réservations salles + passages cowork de la semaine passée dans l'onglet 💰 Revenus
A41: 🗓 Le 1er de chaque mois | B41: Saisir le CA encaissé, les charges réelles payées et le solde bancaire réel dans les onglets correspondants
A42: 🗓 Tous les 3 mois | B42: Vérifier les écarts entre prévisionnel et réalisé — ajuster les taux d'occupation prévisionnels si nécessaire
A43: 🗓 En octobre | B43: Activer la ligne TF (4 200 €) — s'assurer que la provision mensuelle de 350 € est bien constituée
A44: 🗓 En décembre | B44: Régularisation annuelle des charges avec le bailleur : eau (~300 €) + élec communs (~180 €)
A45: 🗓 En janvier 2027 | B45: Appliquer l'indexation ILC du loyer (bail commercial — clause d'échelle mobile)
